Workbook

Sheet 📋 Raw Data
A1: Agricultural Supply Chain & Price Spread Analysis: Azadpur Mandi
A2: DATE | B2: CROP NAME | C2: CATEGORY | D2: SEASON | E2: WHOLESALE PRICE (RS/QUINTAL) | F2: WHOLESALE PRICE (RS/KG) | G2: RETAIL PRICE (RS/KG) | H2: PRICE GAP | I2: SHELF LIFE DAYS | J2: TRANSPORT BURDEN | K2: TRANSPORT BURDEN SCORE | L2: COLD STORAGE AVAILABILITY | M2: MARKUP % | N2: FARMER'S SHARE %
A3: 46136 | B3: Rice | C3: Commodity | D3: ZAID | E3: 3550 | F3: =E3/100 -> 35.5 | G3: 42 | H3: =G3-F3 -> 6.5 | I3: 180 | J3: Low | K3: =IF(J3="Low",1,IF(J3="Medium",2,IF(J3="High",3))) -> 1 | L3: Yes | M3: =H3/F3 -> 0.18309859 | N3: =F3/G3*100 -> 84.52381
A4: 46129 | B4: Rice | C4: Commodity | D4: ZAID | E4: 3550 | F4: =E4/100 -> 35.5 | G4: 42 | H4: =G4-F4 -> 6.5 | I4: 180 | J4: Low | K4: =IF(J4="Low",1,IF(J4="Medium",2,IF(J4="High",3))) -> 1 | L4: Yes | M4: =H4/F4 -> 0.18309859 | N4: =F4/G4*100 -> 84.52381
A5: 46122 | B5: Rice | C5: Commodity | D5: ZAID | E5: 3550 | F5: =E5/100 -> 35.5 | G5: 42 | H5: =G5-F5 -> 6.5 | I5: 180 | J5: Low | K5: =IF(J5="Low",1,IF(J5="Medium",2,IF(J5="High",3))) -> 1 | L5: Yes | M5: =H5/F5 -> 0.18309859 | N5: =F5/G5*100 -> 84.52381
A6: 46114 | B6: Rice | C6: Commodity | D6: ZAID | E6: 3550 | F6: =E6/100 -> 35.5 | G6: 42 | H6: =G6-F6 -> 6.5 | I6: 180 | J6: Low | K6: =IF(J6="Low",1,IF(J6="Medium",2,IF(J6="High",3))) -> 1 | L6: Yes | M6: =H6/F6 -> 0.18309859 | N6: =F6/G6*100 -> 84.52381
A7: 46136 | B7: Onion | C7: Vegetable | D7: ZAID | E7: 1100 | F7: =E7/100 -> 11 | G7: 30 | H7: =G7-F7 -> 19 | I7: 45 | J7: Medium | K7: =IF(J7="Low",1,IF(J7="Medium",2,IF(J7="High",3))) -> 2 | L7: Moderate | M7: =H7/F7 -> 1.7272727 | N7: =F7/G7*100 -> 36.666667
A8: 46129 | B8: Onion | C8: Vegetable | D8: ZAID | E8: 1225 | F8: =E8/100 -> 12.25 | G8: 30 | H8: =G8-F8 -> 17.75 | I8: 45 | J8: Medium | K8: =IF(J8="Low",1,IF(J8="Medium",2,IF(J8="High",3))) -> 2 | L8: Moderate | M8: =H8/F8 -> 1.4489796 | N8: =F8/G8*100 -> 40.833333
A9: 46122 | B9: Onion | C9: Vegetable | D9: ZAID | E9: 1225 | F9: =E9/100 -> 12.25 | G9: 30 | H9: =G9-F9 -> 17.75 | I9: 45 | J9: Medium | K9: =IF(J9="Low",1,IF(J9="Medium",2,IF(J9="High",3))) -> 2 | L9: Moderate | M9: =H9/F9 -> 1.4489796 | N9: =F9/G9*100 -> 40.833333
A10: 46114 | B10: Onion | C10: Vegetable | D10: ZAID | E10: 1200 | F10: =E10/100 -> 12 | G10: 16 | H10: =G10-F10 -> 4 | I10: 45 | J10: Medium | K10: =IF(J10="Low",1,IF(J10="Medium",2,IF(J10="High",3))) -> 2 | L10: Moderate | M10: =H10/F10 -> 0.33333333 | N10: =F10/G10*100 -> 75
A11: 46136 | B11: Brinjal | C11: Vegetable | D11: ZAID | E11: 1920 | F11: =E11/100 -> 19.2 | G11: 50 | H11: =G11-F11 -> 30.8 | I11: 5 | J11: High | K11: =IF(J11="Low",1,IF(J11="Medium",2,IF(J11="High",3))) -> 3 | L11: No | M11: =H11/F11 -> 1.6041667 | N11: =F11/G11*100 -> 38.4
A12: 46129 | B12: Brinjal | C12: Vegetable | D12: ZAID | E12: 2000 | F12: =E12/100 -> 20 | G12: 50 | H12: =G12-F12 -> 30 | I12: 5 | J12: High | K12: =IF(J12="Low",1,IF(J12="Medium",2,IF(J12="High",3))) -> 3 | L12: No | M12: =H12/F12 -> 1.5 | N12: =F12/G12*100 -> 40
A13: 46122 | B13: Brinjal | C13: Vegetable | D13: ZAID | E13: 1850 | F13: =E13/100 -> 18.5 | G13: 52 | H13: =G13-F13 -> 33.5 | I13: 5 | J13: High | K13: =IF(J13="Low",1,IF(J13="Medium",2,IF(J13="High",3))) -> 3 | L13: No | M13: =H13/F13 -> 1.8108108 | N13: =F13/G13*100 -> 35.576923
A14: 46114 | B14: Brinjal | C14: Vegetable | D14: ZAID | E14: 1815 | F14: =E14/100 -> 18.15 | G14: 50 | H14: =G14-F14 -> 31.85 | I14: 5 | J14: High | K14: =IF(J14="Low",1,IF(J14="Medium",2,IF(J14="High",3))) -> 3 | L14: No | M14: =H14/F14 -> 1.7548209 | N14: =F14/G14*100 -> 36.3
... A78: 45889 | B78: Rice | C78: Commodity | D78: KHARIF | E78: 3700 | F78: =E78/100 -> 37 | G78: 39 | H78: =G78-F78 -> 2 | I78: 180 | J78: Low | K78: =IF(J78="Low",1,IF(J78="Medium",2,IF(J78="High",3))) -> 1 | L78: Yes | M78: =H78/F78 -> 0.054054054 | N78: =F78/G78*100 -> 94.871795
A79: 45910 | B79: Onion | C79: Vegetable | D79: KHARIF | E79: =F79*100 -> 1125 | F79: 11.25 | G79: 33 | H79: =G79-F79 -> 21.75 | I79: 45 | J79: Medium | K79: =IF(J79="Low",1,IF(J79="Medium",2,IF(J79="High",3))) -> 2 | L79: Moderate | M79: =H79/F79 -> 1.9333333 | N79: =F79/G79*100 -> 34.090909
A80: 45903 | B80: Onion | C80: Vegetable | D80: KHARIF | E80: =F80*100 -> 1125 | F80: 11.25 | G80: 33 | H80: =G80-F80 -> 21.75 | I80: 45 | J80: Medium | K80: =IF(J80="Low",1,IF(J80="Medium",2,IF(J80="High",3))) -> 2 | L80: Moderate | M80: =H80/F80 -> 1.9333333 | N80: =F80/G80*100 -> 34.090909
A81: 45896 | B81: Onion | C81: Vegetable | D81: KHARIF | E81: =F81*100 -> 1188 | F81: 11.88 | G81: 33 | H81: =G81-F81 -> 21.12 | I81: 45 | J81: Medium | K81: =IF(J81="Low",1,IF(J81="Medium",2,IF(J81="High",3))) -> 2 | L81: Moderate | M81: =H81/F81 -> 1.7777778 | N81: =F81/G81*100 -> 36
A82: 45889 | B82: Onion | C82: Vegetable | D82: KHARIF | E82: =F82*100 -> 1375 | F82: 13.75 | G82: 35 | H82: =G82-F82 -> 21.25 | I82: 45 | J82: Medium | K82: =IF(J82="Low",1,IF(J82="Medium",2,IF(J82="High",3))) -> 2 | L82: Moderate | M82: =H82/F82 -> 1.5454545 | N82: =F82/G82*100 -> 39.285714
A83: 45910 | B83: Brinjal | C83: Vegetable | D83: KHARIF | E83: =F83*100 -> 1750 | F83: 17.5 | G83: 53 | H83: =G83-F83 -> 35.5 | I83: 5 | J83: High | K83: =IF(J83="Low",1,IF(J83="Medium",2,IF(J83="High",3))) -> 3 | L83: No | M83: =H83/F83 -> 2.0285714 | N83: =F83/G83*100 -> 33.018868
A84: 45903 | B84: Brinjal | C84: Vegetable | D84: KHARIF | E84: =F84*100 -> 1400 | F84: 14 | G84: 53 | H84: =G84-F84 -> 39 | I84: 5 | J84: High | K84: =IF(J84="Low",1,IF(J84="Medium",2,IF(J84="High",3))) -> 3 | L84: No | M84: =H84/F84 -> 2.7857143 | N84: =F84/G84*100 -> 26.415094
A85: 45896 | B85: Brinjal | C85: Vegetable | D85: KHARIF | E85: =F85*100 -> 1400 | F85: 14 | G85: 50 | H85: =G85-F85 -> 36 | I85: 5 | J85: High | K85: =IF(J85="Low",1,IF(J85="Medium",2,IF(J85="High",3))) -> 3 | L85: No | M85: =H85/F85 -> 2.5714286 | N85: =F85/G85*100 -> 28
A86: 45889 | B86: Brinjal | C86: Vegetable | D86: KHARIF | E86: =F86*100 -> 1400 | F86: 14 | G86: 53 | H86: =G86-F86 -> 39 | I86: 5 | J86: High | K86: =IF(J86="Low",1,IF(J86="Medium",2,IF(J86="High",3))) -> 3 | L86: No | M86: =H86/F86 -> 2.7857143 | N86: =F86/G86*100 -> 26.415094
A87: 45910 | B87: Wheat | C87: Commodity | D87: KHARIF | E87: 3050 | F87: =E87/100 -> 30.5 | G87: 32 | H87: =G87-F87 -> 1.5 | I87: 150 | J87: Low | K87: =IF(J87="Low",1,IF(J87="Medium",2,IF(J87="High",3))) -> 1 | L87: Yes | M87: =H87/F87 -> 0.049180328 | N87: =F87/G87*100 -> 95.3125
A88: 45903 | B88: Wheat | C88: Commodity | D88: KHARIF | E88: 3050 | F88: =E88/100 -> 30.5 | G88: 32 | H88: =G88-F88 -> 1.5 | I88: 150 | J88: Low | K88: =IF(J88="Low",1,IF(J88="Medium",2,IF(J88="High",3))) -> 1 | L88: Yes | M88: =H88/F88 -> 0.049180328 | N88: =F88/G88*100 -> 95.3125
A89: 45896 | B89: Wheat | C89: Commodity | D89: KHARIF | E89: 3000 | F89: =E89/100 -> 30 | G89: 32 | H89: =G89-F89 -> 2 | I89: 150 | J89: Low | K89: =IF(J89="Low",1,IF(J89="Medium",2,IF(J89="High",3))) -> 1 | L89: Yes | M89: =H89/F89 -> 0.066666667 | N89: =F89/G89*100 -> 93.75
A90: 45889 | B90: Wheat | C90: Commodity | D90: KHARIF | E90: 3000 | F90: =E90/100 -> 30 | G90: 33 | H90: =G90-F90 -> 3 | I90: 150 | J90: Low | K90: =IF(J90="Low",1,IF(J90="Medium",2,IF(J90="High",3))) -> 1 | L90: Yes | M90: =H90/F90 -> 0.1 | N90: =F90/G90*100 -> 90.909091
A91: 45910 | B91: Cauliflower | C91: Vegetable | D91: KHARIF | E91: 1950 | F91: =E91/100 -> 19.5 | G91: 100 | H91: =G91-F91 -> 80.5 | I91: 4 | J91: High | K91: =IF(J91="Low",1,IF(J91="Medium",2,IF(J91="High",3))) -> 3 | L91: Limited | M91: =H91/F91 -> 4.1282051 | N91: =F91/G91*100 -> 19.5
A92: 45903 | B92: Cauliflower | C92: Vegetable | D92: KHARIF | E92: 2067 | F92: =E92/100 -> 20.67 | G92: 90 | H92: =G92-F92 -> 69.33 | I92: 4 | J92: High | K92: =IF(J92="Low",1,IF(J92="Medium",2,IF(J92="High",3))) -> 3 | L92: Limited | M92: =H92/F92 -> 3.3541364 | N92: =F92/G92*100 -> 22.966667
A93: 45896 | B93: Cauliflower | C93: Vegetable | D93: KHARIF | E93: 2200 | F93: =E93/100 -> 22 | G93: 90 | H93: =G93-F93 -> 68 | I93: 4 | J93: High | K93: =IF(J93="Low",1,IF(J93="Medium",2,IF(J93="High",3))) -> 3 | L93: Limited | M93: =H93/F93 -> 3.0909091 | N93: =F93/G93*100 -> 24.444444
A94: 45889 | B94: Cauliflower | C94: Vegetable | D94: KHARIF | E94: 3267 | F94: =E94/100 -> 32.67 | G94: 90 | H94: =G94-F94 -> 57.33 | I94: 4 | J94: High | K94: =IF(J94="Low",1,IF(J94="Medium",2,IF(J94="High",3))) -> 3 | L94: Limited | M94: =H94/F94 -> 1.7548209 | N94: =F94/G94*100 -> 36.3
A95: 45910 | B95: Potato | C95: Vegetable | D95: KHARIF | E95: =F95*100 -> 1400 | F95: 14 | G95: 28 | H95: =G95-F95 -> 14 | I95: 60 | J95: Low | K95: =IF(J95="Low",1,IF(J95="Medium",2,IF(J95="High",3))) -> 1 | L95: Yes | M95: =H95/F95 -> 1 | N95: =F95/G95*100 -> 50
A96: 45903 | B96: Potato | C96: Vegetable | D96: KHARIF | E96: =F96*100 -> 1350 | F96: 13.5 | G96: 28 | H96: =G96-F96 -> 14.5 | I96: 60 | J96: Low | K96: =IF(J96="Low",1,IF(J96="Medium",2,IF(J96="High",3))) -> 1 | L96: Yes | M96: =H96/F96 -> 1.0740741 | N96: =F96/G96*100 -> 48.214286
A97: 45896 | B97: Potato | C97: Vegetable | D97: KHARIF | E97: =F97*100 -> 1350 | F97: 13.5 | G97: 28 | H97: =G97-F97 -> 14.5 | I97: 60 | J97: Low | K97: =IF(J97="Low",1,IF(J97="Medium",2,IF(J97="High",3))) -> 1 | L97: Yes | M97: =H97/F97 -> 1.0740741 | N97: =F97/G97*100 -> 48.214286
A98: 45889 | B98: Potato | C98: Vegetable | D98: KHARIF | E98: =F98*100 -> 1400 | F98: 14 | G98: 27 | H98: =G98-F98 -> 13 | I98: 60 | J98: Low | K98: =IF(J98="Low",1,IF(J98="Medium",2,IF(J98="High",3))) -> 1 | L98: Yes | M98: =H98/F98 -> 0.92857143 | N98: =F98/G98*100 -> 51.851852
A99: 45910 | B99: Tomato | C99: Vegetable | D99: KHARIF | E99: =F99*100 -> 1800 | F99: 18 | G99: 48 | H99: =G99-F99 -> 30 | I99: 7 | J99: High | K99: =IF(J99="Low",1,IF(J99="Medium",2,IF(J99="High",3))) -> 3 | L99: No | M99: =H99/F99 -> 1.6666667 | N99: =F99/G99*100 -> 37.5
A100: 45903 | B100: Tomato | C100: Vegetable | D100: KHARIF | E100: =F100*100 -> 2400 | F100: 24 | G100: 53 | H100: =G100-F100 -> 29 | I100: 7 | J100: High | K100: =IF(J100="Low",1,IF(J100="Medium",2,IF(J100="High",3))) -> 3 | L100: No | M100: =H100/F100 -> 1.2083333 | N100: =F100/G100*100 -> 45.283019
A101: 45896 | B101: Tomato | C101: Vegetable | D101: KHARIF | E101: =F101*100 -> 2600 | F101: 26 | G101: 55 | H101: =G101-F101 -> 29 | I101: 7 | J101: High | K101: =IF(J101="Low",1,IF(J101="Medium",2,IF(J101="High",3))) -> 3 | L101: No | M101: =H101/F101 -> 1.1153846 | N101: =F101/G101*100 -> 47.272727
A102: 45889 | B102: Tomato | C102: Vegetable | D102: KHARIF | E102: =F102*100 -> 3400 | F102: 34 | G102: 78 | H102: =G102-F102 -> 44 | I102: 7 | J102: High | K102: =IF(J102="Low",1,IF(J102="Medium",2,IF(J102="High",3))) -> 3 | L102: No | M102: =H102/F102 -> 1.2941176 | N102: =F102/G102*100 -> 43.589744
A103: 45910 | B103: Ginger | C103: Vegetable | D103: KHARIF | E103: =F103*100 -> 3250 | F103: 32.5 | G103: 150 | H103: =G103-F103 -> 117.5 | I103: 90 | J103: Medium | K103: =IF(J103="Low",1,IF(J103="Medium",2,IF(J103="High",3))) -> 2 | L103: Moderate | M103: =H103/F103 -> 3.6153846 | N103: =F103/G103*100 -> 21.666667
...

Sheet Price chain analysis
A1: PRICE CHAIN ANALYSIS
A3: SECTION 1 - CROP SUMMARY ANALYSIS
A4: Crop | B4: Average Wholesale Price | C4: Average Retail Price | D4: Average Price Gap | E4: Average Markup %
A5: Rice | B5: =AVERAGEIF('📋 Raw Data'!$B2:$B110, "Rice", '📋 Raw Data'!$F2:$F110) -> 36.333333 | C5: =AVERAGEIF('📋 Raw Data'!B2:B110,'📋 Raw Data'!B3,'📋 Raw Data'!G2:G110) -> 41.166667 | D5: =AVERAGE(C5-B5) -> 4.8333333 | E5: =AVERAGEIF('📋 Raw Data'!B2:B110,'📋 Raw Data'!B3,'📋 Raw Data'!M2:M110) -> 0.13385569
A6: Onion | B6: =AVERAGEIF('📋 Raw Data'!$B3:$B110, "Onion", '📋 Raw Data'!$F3:$F110) -> 12.744167 | C6: =AVERAGEIF('📋 Raw Data'!B2:B110,'📋 Raw Data'!B7,'📋 Raw Data'!G2:G110) -> 30.166667 | D6: =AVERAGE(C6-B6) -> 17.4225 | E6: =AVERAGEIF('📋 Raw Data'!B3:B111,'📋 Raw Data'!B7,'📋 Raw Data'!M3:M110) -> 1.3980492
A7: Brinjal | B7: =AVERAGEIF('📋 Raw Data'!$B4:$B112, "Brinjal", '📋 Raw Data'!$F4:$F112) -> 18.11 | C7: =AVERAGEIF('📋 Raw Data'!B3:B111,'📋 Raw Data'!B11,'📋 Raw Data'!G3:G111) -> 51.666667 | D7: =AVERAGE(C7-B7) -> 33.556667 | E7: =AVERAGEIF('📋 Raw Data'!B4:B112,'📋 Raw Data'!B11,'📋 Raw Data'!M4:M112) -> 1.9208428
A8: Wheat | B8: =AVERAGEIF('📋 Raw Data'!$B5:$B113, "Wheat", '📋 Raw Data'!$F5:$F113) -> 28.625 | C8: =AVERAGEIF('📋 Raw Data'!B4:B112,'📋 Raw Data'!B15,'📋 Raw Data'!G4:G112) -> 32.333333 | D8: =AVERAGE(C8-B8) -> 3.7083333 | E8: =AVERAGEIF('📋 Raw Data'!B5:B113,'📋 Raw Data'!B15,'📋 Raw Data'!M5:M113) -> 0.13246818
A9: Cauliflower | B9: =AVERAGEIF('📋 Raw Data'!$B6:$B114, "Cauliflower", '📋 Raw Data'!$F6:$F114) -> 23.945 | C9: =AVERAGEIF('📋 Raw Data'!B5:B113,'📋 Raw Data'!B19,'📋 Raw Data'!G5:G113) -> 64.75 | D9: =AVERAGE(C9-B9) -> 40.805 | E9: =AVERAGEIF('📋 Raw Data'!B6:B114,'📋 Raw Data'!B19,'📋 Raw Data'!M6:M114) -> 1.8221247
A10: Potato | B10: =AVERAGEIF('📋 Raw Data'!$B7:$B115, "Potato", '📋 Raw Data'!$F7:$F115) -> 8.4208333 | C10: =AVERAGEIF('📋 Raw Data'!B6:B114,'📋 Raw Data'!B23,'📋 Raw Data'!G6:G114) -> 21.666667 | D10: =AVERAGE(C10-B10) -> 13.245833 | E10: =AVERAGEIF('📋 Raw Data'!B7:B115,'📋 Raw Data'!B23,'📋 Raw Data'!M7:M115) -> 1.8659666
A11: Tomato | B11: =AVERAGEIF('📋 Raw Data'!$B8:$B116, "Tomato", '📋 Raw Data'!$F8:$F116) -> 25.591667 | C11: =AVERAGEIF('📋 Raw Data'!B7:B115,'📋 Raw Data'!B27,'📋 Raw Data'!G7:G115) -> 46.916667 | D11: =AVERAGE(C11-B11) -> 21.325 | E11: =AVERAGEIF('📋 Raw Data'!B8:B116,'📋 Raw Data'!B27,'📋 Raw Data'!M8:M116) -> 0.95452415
A12: Ginger | B12: =AVERAGEIF('📋 Raw Data'!$B9:$B117, "Ginger", '📋 Raw Data'!$F9:$F117) -> 42.583333 | C12: =AVERAGEIF('📋 Raw Data'!B8:B116,'📋 Raw Data'!B31,'📋 Raw Data'!G8:G116) -> 121.5 | D12: =AVERAGE(C12-B12) -> 78.916667 | E12: =AVERAGEIF('📋 Raw Data'!B9:B117,'📋 Raw Data'!B31,'📋 Raw Data'!M9:M117) -> 2.1066843
A13: Ladyfinger | B13: =AVERAGEIF('📋 Raw Data'!$B10:$B118, "Ladyfinger", '📋 Raw Data'!$F10:$F118) -> 35.333333 | C13: =AVERAGEIF('📋 Raw Data'!B9:B117,'📋 Raw Data'!B38,'📋 Raw Data'!G9:G117) -> 80.916667 | D13: =AVERAGE(C13-B13) -> 45.583333 | E13: =AVERAGEIF('📋 Raw Data'!B10:B118,'📋 Raw Data'!B35,'📋 Raw Data'!M10:M118) -> 1.5395019
A14: AVERAGE | B14: =IFERROR(AVERAGE(B5:B13),"") -> 25.742963 | C14: =IFERROR(AVERAGE(C5:C13),"") -> 54.564815 | D14: =IFERROR(AVERAGE(D5:D13),"") -> 28.821852 | E14: =IFERROR(AVERAGE(E5:E13),"") -> 1.3193353
A16: SECTION 2 - SEASONAL VARIATION
A17: Season | B17: Average Wholesale Price | C17: Average Retail Price | D17: Average Markup %
A18: Zaid | B18: =AVERAGE('📋 Raw Data'!F3:F38) -> 24.213333 | C18: =AVERAGE('📋 Raw Data'!G3:G38) -> 49.444444 | D18: =AVERAGE('📋 Raw Data'!M3:M38) -> 1.2493717
A19: Rabi | B19: =AVERAGE('📋 Raw Data'!F39:F74) -> 29.933056 | C19: =AVERAGE('📋 Raw Data'!G39:G74) -> 55.083333 | D19: =AVERAGE('📋 Raw Data'!M39:M74) -> 0.99901242
A20: Kharif | B20: =AVERAGE('📋 Raw Data'!F75:F110) -> 23.0825 | C20: =AVERAGE('📋 Raw Data'!G75:G110) -> 59.166667 | D20: =AVERAGE('📋 Raw Data'!M75:M110) -> 1.7096218
A23: SECTION 3 - CROP VOLATILITY ANALYSIS
A24: Crop | B24: Max Retail Price | C24: Min Retail Price | D24: Volatility
A25: Rice | B25: =MAX('📋 Raw Data'!G3:G6,'📋 Raw Data'!G75:G78,'📋 Raw Data'!G39:G42) -> 43 | C25: 39 | D25: =B25-C25 -> 4
A26: Onion | B26: =MAX('📋 Raw Data'!$G$7:$G$10,'📋 Raw Data'!$G$43:$G$46,'📋 Raw Data'!$G$79:$G$82) -> 38 | C26: 16 | D26: =B26-C26 -> 22
A27: Brinjal | B27: =MAX('📋 Raw Data'!G11:G14, '📋 Raw Data'!G47:G50,'📋 Raw Data'!G83:G86) -> 53 | C27: 50 | D27: =B27-C27 -> 3
A28: Wheat | B28: =MAX('📋 Raw Data'!G15:G18,'📋 Raw Data'!G51:G54,'📋 Raw Data'!G87:G90) -> 33 | C28: 31 | D28: =B28-C28 -> 2
A29: Cauliflower | B29: =MAX('📋 Raw Data'!G19:G22,'📋 Raw Data'!G55:G58,'📋 Raw Data'!G91:G94) -> 100 | C29: 37 | D29: =B29-C29 -> 63
A30: Potato | B30: =MAX('📋 Raw Data'!G22:G25,'📋 Raw Data'!G59:G62,'📋 Raw Data'!G95:G98) -> 50 | C30: 15 | D30: =B30-C30 -> 35
A31: Tomato | B31: =MAX('📋 Raw Data'!G25:G28,'📋 Raw Data'!G27:G30,'📋 Raw Data'!G63:G66,'📋 Raw Data'!G99:G102) -> 78 | C31: 25 | D31: =B31-C31 -> 53
A32: Ginger | B32: =MAX('📋 Raw Data'!G28:G31,'📋 Raw Data'!G67:G70,'📋 Raw Data'!G103:G106) -> 150 | C32: 100 | D32: =B32-C32 -> 50
A33: Ladyfinger | B33: =MAX('📋 Raw Data'!G32:G35,'📋 Raw Data'!G71:G74,'📋 Raw Data'!G107:G110) -> 120 | C33: 47 | D33: =B33-C33 -> 73
A35: SECTION 4 - PERISHABILITY ANALYSIS
A36: Crop | B36: Shelf Life Days | C36: Average Price Gap | D36: Average Markup %
A37: Rice | B37: 180 | C37: 4.8333333 | D37: 0.13385569
A38: Onion | B38: 45 | C38: 17.4225 | D38: 1.3980492
A39: Brinjal | B39: 5 | C39: 33.556667 | D39: 1.9208428
A40: Wheat | B40: 150 | C40: 3.7083333 | D40: 0.13246818
A41: Cauliflower | B41: 4 | C41: 40.805 | D41: 1.8221247
A42: Potato | B42: 60 | C42: 13.245833 | D42: 1.8659666
A43: Tomato | B43: 7 | C43: 21.325 | D43: 0.95452415
A44: Ginger | B44: 90 | C44: 78.916667 | D44: 2.1066843
A45: Ladyfinger | B45: 3 | C45: 45.583333 | D45: 1.5395019
...

Sheet Dashboards
A1: SECTION 1- CORRELATION | Q1: Shelf Life Day | R1: Markup %
A2: Variable Pair | B2: Correlation | Q2: 180 | R2: 0.18309859
A3: Shelf Life vs Markup % | B3: =CORREL('📋 Raw Data'!I3:I110,'📋 Raw Data'!M3:M110) -> -0.49826008 | Q3: 180 | R3: 0.18309859
A4: Transport Burden vs Markup % | B4: =CORREL('📋 Raw Data'!K3:K110,'📋 Raw Data'!M3:M110) -> 0.35613688 | Q4: 180 | R4: 0.18309859
Q5: 180 | R5: 0.18309859
A6: Interpretation: Shelf life showed a moderate negative correlation (-0.498) with markup percentage, indicating that highly perishable crops generally experience higher retail markups. Transport burden showed a moderate positive correlation (0.356), suggesting logistics difficulty and transportation costs contribute to supply-chain price inflation between wholesale and retail markets. | Q6: 45 | R6: 1.7272727
Q7: 45 | R7: 1.4489796
Q8: 45 | R8: 1.4489796
Q9: 45 | R9: 0.33333333
Q10: 5 | R10: 1.6041667
Q11: 5 | R11: 1.5
Q12: 5 | R12: 1.8108108
Q13: 5 | R13: 1.7548209
Q14: 150 | R14: 0.22222222
A15: SECTION 2 - WHOLESALE vs RETAIL PRICES | Q15: 150 | R15: 0.22222222
Q16: 150 | R16: 0.21100917
Q17: 150 | R17: 0.21100917
Q18: 4 | R18: 0.875
Q19: 4 | R19: 1.2333333
Q20: 4 | R20: 0.56666667
Q21: 4 | R21: 2.3333333
Q22: 60 | R22: 1.5423729
Q23: 60 | R23: 2.6866359
Q24: 60 | R24: 2.9170507
Q25: 60 | R25: 2.5294118
Q26: 7 | R26: 1.5
Q27: 7 | R27: 0.70731707
... Q31: 90 | R31: 1.2156863
A32: Interpretation : The bar chart compares average wholesale and retail prices of different crops. Retail prices are consistently higher than wholesale prices for all crops, indicating the presence of markup across the supply chain. Crops like ginger and ladyfinger show a larger price difference, suggesting higher transportation, storage, or intermediary costs, while crops such as rice and wheat show relatively smaller differences and more stable pricing. | Q32: 90 | R32: 1.0980392
Q33: 90 | R33: 1.2222222
Q34: 3 | R34: 2.1578947
Q35: 3 | R35: 2.32
Q36: 3 | R36: 1.8064516
Q37: 3 | R37: 1.3513514
Q38: 180 | R38: 0.16216216
Q39: 180 | R39: 0.16216216
Q40: 180 | R40: 0.16666667
A41: SECTION 3- SHELF LIFE vs MARKUP PERCENTAGE | Q41: 180 | R41: 0.16666667
Q42: 45 | R42: 0.74825175
Q43: 45 | R43: 1.1917808
...
